Workbook

Sheet README
A1: Cheerio Next Best Action: financial model (assignment draft, v2)
A3: What this is: a transparent, formula-driven business-case model for a rules-based feature-discovery recommendation. It is built from labelled placeholders, NOT from Cheerio's data. Do not present its outputs as forecasts.
A4: Currency: INR. Units are in column B. Scenarios: Conservative (C), Base (D), Optimistic (E). Colour legend: blue = editable input; black = formula; green = link to another sheet; yellow fill = hypothesis or placeholder to review.
A6: Two economic views (same horizon H and same cost basis in both)
A7: Scenario 1, single cohort: the programme is launched once to the existing eligible base. No later cohorts are added, but the full programme cost runs for H months. This is the cost of proving the idea on today's base and is deliberately harsh.
A8: Scenario 2, recurring monthly rollout: the same launch cohort PLUS a new cohort of newly eligible, exposed businesses each month (inflow is an illustrative placeholder). Scenario 2 includes Scenario 1; the two are not additive.
A10: How retention benefit is derived (changed in v2)
A11: Only INCREMENTAL activators (treatment activation minus control activation) are assumed to churn less than control. Weaker activation therefore means a weaker retention effect automatically. Revenue is the plan price on the extra retained account-months, each counted once. Non-activators are assumed unaffected.
A12: The observable a holdout would read out is shown as an expected treatment-minus-holdout survival gap on the Revenue sheet. Adoption does not cause retention by assumption alone; the churn input is a hypothesis to be tested.
A14: Sheets
A15: Assumptions: all inputs and their type. Adoption funnel: launch cohort funnel. Cost model: fixed vs variable and launch-month unit costs. Cohort engine: monthly cohorts, retained account-months (up to 24 months). Revenue and business case: both scenarios, break-even, ROI sensitivity to worse churn and worse activation. Billing and audit: three pricing options over the same horizon and cost basis, plus monthly audit checks.
A17: ROI definition: operating contribution / total programme cost, where contribution = gross profit on attributable revenue minus programme cost. Gross margin and operating contribution are reported separately.
A18: Not modelled: cannibalisation, seasonality, support cost, cost of billing changes (unless the build-cost input is raised), discounting, taxes. Audit 'observed' values are EXAMPLE data. Token and FX prices are unverified placeholders (AI layer is off).

Sheet Assumptions
A1: Assumptions
A2: Edit blue cells only. Columns C/D/E = Conservative / Base / Optimistic. Where scenarios do not differ, C and E link to D.
A4: Assumption | B4: Unit | C4: Conservative | D4: Base | E4: Optimistic | F4: Type | G4: Note / source
A5: Customer base and exposure
A6: Active businesses | B6: businesses | C6: =D6 -> 5000 | D6: 5000 | E6: =D6 -> 5000 | F6: Supplied (assignment) | G6: Given in the assignment brief.
A7: Share of active businesses that are eligible (send campaigns, no automation yet) | B7: % of active | C7: 0.3 | D7: 0.4 | E7: 0.5 | F7: Hypothesis | G7: Unknown. Must be measured from Cheerio's product events.
A8: Eligible businesses exposed to a recommendation in the month | B8: % of eligible | C8: 0.7 | D8: 0.8 | E8: 0.9 | F8: Hypothesis | G8: Depends on login frequency. Measure.
A9: Recurring rollout only: newly eligible businesses per month | B9: % of active per month | C9: 0.015 | D9: 0.02 | E9: 0.03 | F9: Hypothesis | G9: Illustrative placeholder; Cheerio's real inflow is unknown. Each month this share of active businesses becomes eligible and the exposure rate applies.
A10: Recommendation impressions per exposed business per month | B10: impressions | C10: =D10 -> 2.5 | D10: 2.5 | E10: =D10 -> 2.5 | F10: Hypothesis | G10: Capped by suppression rules (max 1 shown at a time).
A11: Funnel conversion (stage rates)
A12: Click rate | B12: % of exposed | C12: 0.25 | D12: 0.3 | E12: 0.35 | F12: Hypothesis | G12: Base set near the prototype's synthetic funnel, which is itself illustrative.
A13: Setup start rate | B13: % of clicks | C13: 0.6 | D13: 0.68 | E13: 0.72 | F13: Hypothesis | G13: As above.
A14: Setup completion (activation) rate | B14: % of starts | C14: 0.55 | D14: 0.63 | E14: 0.7 | F14: Hypothesis | G14: As above.
A15: Activation rate in control group (no recommendation, same period) | B15: % of exposed-equivalent | C15: 0.06 | D15: 0.05 | E15: 0.04 | F15: Hypothesis | G15: Organic adoption. Must come from a holdout. Conservative = higher control.
A16: Retention (illustrative; NOT Cheerio's real churn)
A17: Monthly churn, control group | B17: % per month | C17: =D17 -> 0.05 | D17: 0.05 | E17: =D17 -> 0.05 | F17: Illustrative placeholder | G17: Placeholder. Replace with measured churn.
A18: Monthly churn of accounts that activate BECAUSE of the recommendation (incremental activators) | B18: % per month | C18: 0.04 | D18: 0.035 | E18: 0.03 | F18: Hypothesis | G18: Placeholder hypothesis. Compared with control churn above. Retention benefit applies ONLY to incremental activators, so weaker activation automatically means weaker retention.
A19: Months from exposure to activation before any retention benefit starts | B19: months | C19: =D19 -> 1 | D19: 1 | E19: =D19 -> 1 | F19: Hypothesis | G19: Placeholder. Activation is not instant.
A20: Evaluation horizon | B20: months | C20: =D20 -> 12 | D20: 12 | E20: =D20 -> 12 | F20: Illustrative placeholder | G20: Evaluation window used for BOTH cohort scenarios (maximum 24 in this workbook).
A21: Pricing and margin
A22: Average monthly plan price | B22: INR / account / month | C22: =D22 -> 2500 | D22: 2500 | E22: =D22 -> 2500 | F22: Illustrative placeholder | G22: Placeholder. Cheerio's real average plan price is not known.
A23: Gross margin on plan revenue (serving cost excluded from this model otherwise) | B23: % of plan revenue | C23: =D23 -> 0.85 | D23: 0.85 | E23: =D23 -> 0.85 | F23: Illustrative placeholder | G23: Placeholder.
A24: Monthly programme costs (INR per month)
A25: Hosting | B25: INR / month | C25: =D25 -> 6000 | D25: 6000 | E25: =D25 -> 6000 | F25: Illustrative placeholder | G25: Placeholder.
A26: Analytics and experimentation tooling | B26: INR / month | C26: =D26 -> 4000 | D26: 4000 | E26: =D26 -> 4000 | F26: Illustrative placeholder | G26: Placeholder.
A27: Development and maintenance allocation | B27: INR / month | C27: =D27 -> 25000 | D27: 25000 | E27: =D27 -> 25000 | F27: Illustrative placeholder | G27: Placeholder allocation of team time.
A28: Other operating expenses | B28: INR / month | C28: =D28 -> 2000 | D28: 2000 | E28: =D28 -> 2000 | F28: Illustrative placeholder | G28: Placeholder.
A29: Optional AI layer (OFF for the MVP; rules-based engine has no per-impression model call)
A30: AI layer enabled? (1 = yes, 0 = no) | B30: flag | C30: =D30 -> 0 | D30: 0 | E30: =D30 -> 0 | F30: Supplied (assignment) | G30: MVP decision: deterministic rules. Set 1 to see token cost.
A31: Share of impressions that make a model call | B31: % of impressions | C31: =D31 -> 1 | D31: 1 | E31: =D31 -> 1 | F31: Illustrative placeholder | G31: Only used if AI layer is on.
A32: Input tokens per AI-assisted recommendation | B32: tokens | C32: =D32 -> 1200 | D32: 1200 | E32: =D32 -> 1200 | F32: Illustrative placeholder | G32: Placeholder.
A33: Output tokens per AI-assisted recommendation | B33: tokens | C33: =D33 -> 250 | D33: 250 | E33: =D33 -> 250 | F33: Illustrative placeholder | G33: Placeholder.
A34: Input token price | B34: USD per 1M tokens | C34: =D34 -> 3 | D34: 3 | E34: =D34 -> 3 | F34: External benchmark: verify | G34: UNVERIFIED placeholder. Source: not checked. Access date: not verified. Verify with provider pricing page.
A35: Output token price | B35: USD per 1M tokens | C35: =D35 -> 15 | D35: 15 | E35: =D35 -> 15 | F35: External benchmark: verify | G35: UNVERIFIED placeholder. Source: not checked. Access date: not verified.
A36: Exchange rate | B36: INR per USD | C36: =D36 -> 85 | D36: 85 | E36: =D36 -> 85 | F36: External benchmark: verify | G36: UNVERIFIED placeholder. Use the rate on the date you verify prices.
A37: Pricing options (used on Billing and audit, Base column only)
A38: Share of eligible businesses already on the higher plan | B38: % of eligible | C38: =D38 -> 0.2 | D38: 0.2 | E38: =D38 -> 0.2 | F38: Hypothesis | G38: Option B gates discovery to these accounts.
A39: Upgrade rate among eligible accounts not on the higher plan | B39: % of eligible per cohort | C39: =D39 -> 0.015 | D39: 0.015 | E39: =D39 -> 0.015 | F39: Hypothesis | G39: Share converting once per exposure cohort; assumed fully incremental (no cannibalisation), which favours B.
A40: Higher-plan price uplift | B40: INR / account / month | C40: =D40 -> 1000 | D40: 1000 | E40: =D40 -> 1000 | F40: Illustrative placeholder | G40: Placeholder.
A41: Paid add-on price | B41: INR / account / month | C41: =D41 -> 499 | D41: 499 | E41: =D41 -> 499 | F41: Illustrative placeholder | G41: Placeholder.
...

Sheet Adoption funnel
A1: Adoption funnel: launch cohort = the existing eligible base (later cohorts are on the Cohort engine sheet)
A3: Metric | B3: Unit | C3: Conservative | D3: Base | E3: Optimistic | F3: Formula logic
A4: Eligible businesses | B4: businesses | C4: =Assumptions!$C$6*Assumptions!$C$7 -> 1500 | D4: =Assumptions!$D$6*Assumptions!$D$7 -> 2000 | E4: =Assumptions!$E$6*Assumptions!$E$7 -> 2500 | F4: active x eligible share
A5: Businesses exposed to a recommendation | B5: businesses | C5: =C4*Assumptions!$C$8 -> 1050 | D5: =D4*Assumptions!$D$8 -> 1600 | E5: =E4*Assumptions!$E$8 -> 2250 | F5: eligible x exposure rate
A6: Recommendation impressions | B6: impressions | C6: =C5*Assumptions!$C$10 -> 2625 | D6: =D5*Assumptions!$D$10 -> 4000 | E6: =E5*Assumptions!$E$10 -> 5625 | F6: exposed x impressions per business
A7: Businesses clicking a recommendation | B7: businesses | C7: =C5*Assumptions!$C$12 -> 262.5 | D7: =D5*Assumptions!$D$12 -> 480 | E7: =E5*Assumptions!$E$12 -> 787.5 | F7: exposed x click rate
A8: Setup starts | B8: businesses | C8: =C7*Assumptions!$C$13 -> 157.5 | D8: =D7*Assumptions!$D$13 -> 326.4 | E8: =E7*Assumptions!$E$13 -> 567 | F8: clicks x start rate
A9: Successful activations (treatment) | B9: businesses | C9: =C8*Assumptions!$C$14 -> 86.625 | D9: =D8*Assumptions!$D$14 -> 205.632 | E9: =E8*Assumptions!$E$14 -> 396.9 | F9: starts x completion rate
A10: End-to-end activation rate among exposed | B10: % of exposed | C10: =IF(C5=0,0,C9/C5) -> 0.0825 | D10: =IF(D5=0,0,D9/D5) -> 0.12852 | E10: =IF(E5=0,0,E9/E5) -> 0.1764 | F10: activations / exposed
A11: Expected activations in control (same exposed count) | B11: businesses | C11: =C5*Assumptions!$C$15 -> 63 | D11: =D5*Assumptions!$D$15 -> 80 | E11: =E5*Assumptions!$E$15 -> 90 | F11: exposed x control activation rate
A12: Incremental activations vs control | B12: businesses | C12: =C9-C11 -> 23.625 | D12: =D9-D11 -> 125.632 | E12: =E9-E11 -> 306.9 | F12: treatment - control
A13: Incremental share of treatment activations | B13: % | C13: =IF(C9=0,0,C12/C9) -> 0.27272727 | D13: =IF(D9=0,0,D12/D9) -> 0.61095549 | E13: =IF(E9=0,0,E12/E9) -> 0.77324263 | F13: incremental / treatment activations
A14: Relative lift in activation vs control | B14: % | C14: =IF(C11=0,0,C9/C11-1) -> 0.375 | D14: =IF(D11=0,0,D9/D11-1) -> 1.5704 | E14: =IF(E11=0,0,E9/E11-1) -> 3.41 | F14: treatment / control - 1
A16: Reading note: activations that would have happened anyway are NOT credited to the programme; only incremental activations are.

Sheet Cost model
A1: Cost model (INR per month)
A3: Item | B3: Unit | C3: Conservative | D3: Base | E3: Optimistic | F3: Type / logic
A4: Fixed costs
A5: Hosting | B5: INR / month | C5: =Assumptions!$C$25 -> 6000 | D5: =Assumptions!$D$25 -> 6000 | E5: =Assumptions!$E$25 -> 6000 | F5: fixed
A6: Analytics and experimentation tooling | B6: INR / month | C6: =Assumptions!$C$26 -> 4000 | D6: =Assumptions!$D$26 -> 4000 | E6: =Assumptions!$E$26 -> 4000 | F6: fixed
A7: Development and maintenance allocation | B7: INR / month | C7: =Assumptions!$C$27 -> 25000 | D7: =Assumptions!$D$27 -> 25000 | E7: =Assumptions!$E$27 -> 25000 | F7: fixed (allocation)
A8: Other operating expenses | B8: INR / month | C8: =Assumptions!$C$28 -> 2000 | D8: =Assumptions!$D$28 -> 2000 | E8: =Assumptions!$E$28 -> 2000 | F8: fixed
A9: Total fixed cost | B9: INR / month | C9: =SUM(C5:C8) -> 37000 | D9: =SUM(D5:D8) -> 37000 | E9: =SUM(E5:E8) -> 37000 | F9: sum
A10: Variable cost: optional LLM tokens (zero only because the AI layer is switched off)
A11: Token cost per AI-assisted recommendation | B11: INR / call | C11: =(Assumptions!$C$32/1000000*Assumptions!$C$34+Assumptions!$C$33/1000000*Assumptions!$C$35)*Assumptions!$C$36 -> 0.62475 | D11: =(Assumptions!$D$32/1000000*Assumptions!$D$34+Assumptions!$D$33/1000000*Assumptions!$D$35)*Assumptions!$D$36 -> 0.62475 | E11: =(Assumptions!$E$32/1000000*Assumptions!$E$34+Assumptions!$E$33/1000000*Assumptions!$E$35)*Assumptions!$E$36 -> 0.62475 | F11: (in/1M x in price + out/1M x out price) x FX. Prices unverified.
A12: AI calls in the launch month | B12: calls | C12: ='Adoption funnel'!C6*Assumptions!$C$31*Assumptions!$C$30 -> 0 | D12: ='Adoption funnel'!D6*Assumptions!$D$31*Assumptions!$D$30 -> 0 | E12: ='Adoption funnel'!E6*Assumptions!$E$31*Assumptions!$E$30 -> 0 | F12: impressions x AI share x AI flag
A13: Variable AI token cost | B13: INR / month | C13: =C11*C12 -> 0 | D13: =D11*D12 -> 0 | E13: =E11*E12 -> 0 | F13: cost per call x calls
A14: Launch-month operating cost (fixed + AI at launch-month impressions) | B14: INR / month | C14: =C9+C13 -> 37000 | D14: =D9+D13 -> 37000 | E14: =E9+E13 -> 37000 | F14: fixed + variable
A15: Unit costs
A16: Launch-month cost per eligible business | B16: INR / eligible | C16: =IF('Adoption funnel'!C4=0,0,C14/'Adoption funnel'!C4) -> 24.666667 | D16: =IF('Adoption funnel'!D4=0,0,D14/'Adoption funnel'!D4) -> 18.5 | E16: =IF('Adoption funnel'!E4=0,0,E14/'Adoption funnel'!E4) -> 14.8 | F16: total / eligible
A17: Launch-month cost per exposed business | B17: INR / exposed | C17: =IF('Adoption funnel'!C5=0,0,C14/'Adoption funnel'!C5) -> 35.238095 | D17: =IF('Adoption funnel'!D5=0,0,D14/'Adoption funnel'!D5) -> 23.125 | E17: =IF('Adoption funnel'!E5=0,0,E14/'Adoption funnel'!E5) -> 16.444444 | F17: total / exposed
A18: Launch-month cost per successful activation | B18: INR / activation | C18: =IF('Adoption funnel'!C9=0,0,C14/'Adoption funnel'!C9) -> 427.12843 | D18: =IF('Adoption funnel'!D9=0,0,D14/'Adoption funnel'!D9) -> 179.93308 | E18: =IF('Adoption funnel'!E9=0,0,E14/'Adoption funnel'!E9) -> 93.222474 | F18: total / treatment activations
A19: Launch-month cost per incremental activation | B19: INR / activation | C19: =IF('Adoption funnel'!C12<=0,0,C14/'Adoption funnel'!C12) -> 1566.1376 | D19: =IF('Adoption funnel'!D12<=0,0,D14/'Adoption funnel'!D12) -> 294.51095 | E19: =IF('Adoption funnel'!E12<=0,0,E14/'Adoption funnel'!E12) -> 120.56044 | F19: total / incremental activations (0 if none)
A20: Cost structure
A21: Fixed share of total cost | B21: % | C21: =IF(C14=0,0,C9/C14) -> 1 | D21: =IF(D14=0,0,D9/D14) -> 1 | E21: =IF(E14=0,0,E9/E14) -> 1 | F21: fixed / total
A22: Variable share of total cost | B22: % | C22: =IF(C14=0,0,C13/C14) -> 0 | D22: =IF(D14=0,0,D13/D14) -> 0 | E22: =IF(E14=0,0,E13/E14) -> 0 | F22: variable / total
A24: Design choice: a deterministic rules engine means each impression costs no model call. Cost is almost entirely fixed (team time, hosting, tooling). If an LLM layer is added, set the AI flag to 1 on Assumptions.

Sheet Cohort engine
A1: Cohort engine: monthly exposure cohorts and retained account-months
A2: Cohort m is exposed in month m. L = months left in the window; benefit months = L minus the activation lag. Capacity: horizon up to 24 months. Cohort 1 is the launch cohort (existing eligible base); later cohorts are newly eligible businesses (Assumptions).
B3: Conservative | I3: Base | P3: Optimistic
A4: Month m | B4: Exposed in cohort | C4: Months in window (L) | D4: Benefit months (L - lag) | E4: Control retained months per exposed, L | F4: Control retained months per exposed, benefit months | G4: Activator retained months per exposed, benefit months | I4: Exposed in cohort | J4: Months in window (L) | K4: Benefit months (L - lag) | L4: Control retained months per exposed, L | M4: Control retained months per exposed, benefit months | N4: Activator retained months per exposed, benefit months | P4: Exposed in cohort | Q4: Months in window (L) | R4: Benefit months (L - lag) | S4: Control retained months per exposed, L | T4: Control retained months per exposed, benefit months | U4: Activator retained months per exposed, benefit months
A5: 1 | B5: =IF($A5<=Assumptions!$C$20,'Adoption funnel'!C5,0) -> 1050 | C5: =IF($A5<=Assumptions!$C$20,Assumptions!$C$20-$A5+1,0) -> 12 | D5: =MAX(0,C5-Assumptions!$C$19) -> 11 | E5: =IF(C5=0,0,IF((1-Assumptions!$C$17)=1,C5,(1-Assumptions!$C$17)*(1-(1-Assumptions!$C$17)^C5)/(1-(1-Assumptions!$C$17)))) -> 8.7331583 | F5: =IF(D5=0,0,IF((1-Assumptions!$C$17)=1,D5,(1-Assumptions!$C$17)*(1-(1-Assumptions!$C$17)^D5)/(1-(1-Assumptions!$C$17)))) -> 8.1927982 | G5: =IF(D5=0,0,IF((1-Assumptions!$C$18)=1,D5,(1-Assumptions!$C$18)*(1-(1-Assumptions!$C$18)^D5)/(1-(1-Assumptions!$C$18)))) -> 8.6822561 | I5: =IF($A5<=Assumptions!$D$20,'Adoption funnel'!D5,0) -> 1600 | J5: =IF($A5<=Assumptions!$D$20,Assumptions!$D$20-$A5+1,0) -> 12 | K5: =MAX(0,J5-Assumptions!$D$19) -> 11 | L5: =IF(J5=0,0,IF((1-Assumptions!$D$17)=1,J5,(1-Assumptions!$D$17)*(1-(1-Assumptions!$D$17)^J5)/(1-(1-Assumptions!$D$17)))) -> 8.7331583 | M5: =IF(K5=0,0,IF((1-Assumptions!$D$17)=1,K5,(1-Assumptions!$D$17)*(1-(1-Assumptions!$D$17)^K5)/(1-(1-Assumptions!$D$17)))) -> 8.1927982 | N5: =IF(K5=0,0,IF((1-Assumptions!$D$18)=1,K5,(1-Assumptions!$D$18)*(1-(1-Assumptions!$D$18)^K5)/(1-(1-Assumptions!$D$18)))) -> 8.9394183 | P5: =IF($A5<=Assumptions!$E$20,'Adoption funnel'!E5,0) -> 2250 | Q5: =IF($A5<=Assumptions!$E$20,Assumptions!$E$20-$A5+1,0) -> 12 | R5: =MAX(0,Q5-Assumptions!$E$19) -> 11 | S5: =IF(Q5=0,0,IF((1-Assumptions!$E$17)=1,Q5,(1-Assumptions!$E$17)*(1-(1-Assumptions!$E$17)^Q5)/(1-(1-Assumptions!$E$17)))) -> 8.7331583 | T5: =IF(R5=0,0,IF((1-Assumptions!$E$17)=1,R5,(1-Assumptions!$E$17)*(1-(1-Assumptions!$E$17)^R5)/(1-(1-Assumptions!$E$17)))) -> 8.1927982 | U5: =IF(R5=0,0,IF((1-Assumptions!$E$18)=1,R5,(1-Assumptions!$E$18)*(1-(1-Assumptions!$E$18)^R5)/(1-(1-Assumptions!$E$18)))) -> 9.2052546
A6: 2 | B6: =IF($A6<=Assumptions!$C$20,Assumptions!$C$6*Assumptions!$C$9*Assumptions!$C$8,0) -> 52.5 | C6: =IF($A6<=Assumptions!$C$20,Assumptions!$C$20-$A6+1,0) -> 11 | D6: =MAX(0,C6-Assumptions!$C$19) -> 10 | E6: =IF(C6=0,0,IF((1-Assumptions!$C$17)=1,C6,(1-Assumptions!$C$17)*(1-(1-Assumptions!$C$17)^C6)/(1-(1-Assumptions!$C$17)))) -> 8.1927982 | F6: =IF(D6=0,0,IF((1-Assumptions!$C$17)=1,D6,(1-Assumptions!$C$17)*(1-(1-Assumptions!$C$17)^D6)/(1-(1-Assumptions!$C$17)))) -> 7.6239982 | G6: =IF(D6=0,0,IF((1-Assumptions!$C$18)=1,D6,(1-Assumptions!$C$18)*(1-(1-Assumptions!$C$18)^D6)/(1-(1-Assumptions!$C$18)))) -> 8.0440167 | I6: =IF($A6<=Assumptions!$D$20,Assumptions!$D$6*Assumptions!$D$9*Assumptions!$D$8,0) -> 80 | J6: =IF($A6<=Assumptions!$D$20,Assumptions!$D$20-$A6+1,0) -> 11 | K6: =MAX(0,J6-Assumptions!$D$19) -> 10 | L6: =IF(J6=0,0,IF((1-Assumptions!$D$17)=1,J6,(1-Assumptions!$D$17)*(1-(1-Assumptions!$D$17)^J6)/(1-(1-Assumptions!$D$17)))) -> 8.1927982 | M6: =IF(K6=0,0,IF((1-Assumptions!$D$17)=1,K6,(1-Assumptions!$D$17)*(1-(1-Assumptions!$D$17)^K6)/(1-(1-Assumptions!$D$17)))) -> 7.6239982 | N6: =IF(K6=0,0,IF((1-Assumptions!$D$18)=1,K6,(1-Assumptions!$D$18)*(1-(1-Assumptions!$D$18)^K6)/(1-(1-Assumptions!$D$18)))) -> 8.2636459 | P6: =IF($A6<=Assumptions!$E$20,Assumptions!$E$6*Assumptions!$E$9*Assumptions!$E$8,0) -> 135 | Q6: =IF($A6<=Assumptions!$E$20,Assumptions!$E$20-$A6+1,0) -> 11 | R6: =MAX(0,Q6-Assumptions!$E$19) -> 10 | S6: =IF(Q6=0,0,IF((1-Assumptions!$E$17)=1,Q6,(1-Assumptions!$E$17)*(1-(1-Assumptions!$E$17)^Q6)/(1-(1-Assumptions!$E$17)))) -> 8.1927982 | T6: =IF(R6=0,0,IF((1-Assumptions!$E$17)=1,R6,(1-Assumptions!$E$17)*(1-(1-Assumptions!$E$17)^R6)/(1-(1-Assumptions!$E$17)))) -> 7.6239982 | U6: =IF(R6=0,0,IF((1-Assumptions!$E$18)=1,R6,(1-Assumptions!$E$18)*(1-(1-Assumptions!$E$18)^R6)/(1-(1-Assumptions!$E$18)))) -> 8.4899532
A7: 3 | B7: =IF($A7<=Assumptions!$C$20,Assumptions!$C$6*Assumptions!$C$9*Assumptions!$C$8,0) -> 52.5 | C7: =IF($A7<=Assumptions!$C$20,Assumptions!$C$20-$A7+1,0) -> 10 | D7: =MAX(0,C7-Assumptions!$C$19) -> 9 | E7: =IF(C7=0,0,IF((1-Assumptions!$C$17)=1,C7,(1-Assumptions!$C$17)*(1-(1-Assumptions!$C$17)^C7)/(1-(1-Assumptions!$C$17)))) -> 7.6239982 | F7: =IF(D7=0,0,IF((1-Assumptions!$C$17)=1,D7,(1-Assumptions!$C$17)*(1-(1-Assumptions!$C$17)^D7)/(1-(1-Assumptions!$C$17)))) -> 7.0252612 | G7: =IF(D7=0,0,IF((1-Assumptions!$C$18)=1,D7,(1-Assumptions!$C$18)*(1-(1-Assumptions!$C$18)^D7)/(1-(1-Assumptions!$C$18)))) -> 7.3791841 | I7: =IF($A7<=Assumptions!$D$20,Assumptions!$D$6*Assumptions!$D$9*Assumptions!$D$8,0) -> 80 | J7: =IF($A7<=Assumptions!$D$20,Assumptions!$D$20-$A7+1,0) -> 10 | K7: =MAX(0,J7-Assumptions!$D$19) -> 9 | L7: =IF(J7=0,0,IF((1-Assumptions!$D$17)=1,J7,(1-Assumptions!$D$17)*(1-(1-Assumptions!$D$17)^J7)/(1-(1-Assumptions!$D$17)))) -> 7.6239982 | M7: =IF(K7=0,0,IF((1-Assumptions!$D$17)=1,K7,(1-Assumptions!$D$17)*(1-(1-Assumptions!$D$17)^K7)/(1-(1-Assumptions!$D$17)))) -> 7.0252612 | N7: =IF(K7=0,0,IF((1-Assumptions!$D$18)=1,K7,(1-Assumptions!$D$18)*(1-(1-Assumptions!$D$18)^K7)/(1-(1-Assumptions!$D$18)))) -> 7.5633636 | P7: =IF($A7<=Assumptions!$E$20,Assumptions!$E$6*Assumptions!$E$9*Assumptions!$E$8,0) -> 135 | Q7: =IF($A7<=Assumptions!$E$20,Assumptions!$E$20-$A7+1,0) -> 10 | R7: =MAX(0,Q7-Assumptions!$E$19) -> 9 | S7: =IF(Q7=0,0,IF((1-Assumptions!$E$17)=1,Q7,(1-Assumptions!$E$17)*(1-(1-Assumptions!$E$17)^Q7)/(1-(1-Assumptions!$E$17)))) -> 7.6239982 | T7: =IF(R7=0,0,IF((1-Assumptions!$E$17)=1,R7,(1-Assumptions!$E$17)*(1-(1-Assumptions!$E$17)^R7)/(1-(1-Assumptions!$E$17)))) -> 7.0252612 | U7: =IF(R7=0,0,IF((1-Assumptions!$E$18)=1,R7,(1-Assumptions!$E$18)*(1-(1-Assumptions!$E$18)^R7)/(1-(1-Assumptions!$E$18)))) -> 7.7525291
A8: 4 | B8: =IF($A8<=Assumptions!$C$20,Assumptions!$C$6*Assumptions!$C$9*Assumptions!$C$8,0) -> 52.5 | C8: =IF($A8<=Assumptions!$C$20,Assumptions!$C$20-$A8+1,0) -> 9 | D8: =MAX(0,C8-Assumptions!$C$19) -> 8 | E8: =IF(C8=0,0,IF((1-Assumptions!$C$17)=1,C8,(1-Assumptions!$C$17)*(1-(1-Assumptions!$C$17)^C8)/(1-(1-Assumptions!$C$17)))) -> 7.0252612 | F8: =IF(D8=0,0,IF((1-Assumptions!$C$17)=1,D8,(1-Assumptions!$C$17)*(1-(1-Assumptions!$C$17)^D8)/(1-(1-Assumptions!$C$17)))) -> 6.3950118 | G8: =IF(D8=0,0,IF((1-Assumptions!$C$18)=1,D8,(1-Assumptions!$C$18)*(1-(1-Assumptions!$C$18)^D8)/(1-(1-Assumptions!$C$18)))) -> 6.6866501 | I8: =IF($A8<=Assumptions!$D$20,Assumptions!$D$6*Assumptions!$D$9*Assumptions!$D$8,0) -> 80 | J8: =IF($A8<=Assumptions!$D$20,Assumptions!$D$20-$A8+1,0) -> 9 | K8: =MAX(0,J8-Assumptions!$D$19) -> 8 | L8: =IF(J8=0,0,IF((1-Assumptions!$D$17)=1,J8,(1-Assumptions!$D$17)*(1-(1-Assumptions!$D$17)^J8)/(1-(1-Assumptions!$D$17)))) -> 7.0252612 | M8: =IF(K8=0,0,IF((1-Assumptions!$D$17)=1,K8,(1-Assumptions!$D$17)*(1-(1-Assumptions!$D$17)^K8)/(1-(1-Assumptions!$D$17)))) -> 6.3950118 | N8: =IF(K8=0,0,IF((1-Assumptions!$D$18)=1,K8,(1-Assumptions!$D$18)*(1-(1-Assumptions!$D$18)^K8)/(1-(1-Assumptions!$D$18)))) -> 6.8376825 | P8: =IF($A8<=Assumptions!$E$20,Assumptions!$E$6*Assumptions!$E$9*Assumptions!$E$8,0) -> 135 | Q8: =IF($A8<=Assumptions!$E$20,Assumptions!$E$20-$A8+1,0) -> 9 | R8: =MAX(0,Q8-Assumptions!$E$19) -> 8 | S8: =IF(Q8=0,0,IF((1-Assumptions!$E$17)=1,Q8,(1-Assumptions!$E$17)*(1-(1-Assumptions!$E$17)^Q8)/(1-(1-Assumptions!$E$17)))) -> 7.0252612 | T8: =IF(R8=0,0,IF((1-Assumptions!$E$17)=1,R8,(1-Assumptions!$E$17)*(1-(1-Assumptions!$E$17)^R8)/(1-(1-Assumptions!$E$17)))) -> 6.3950118 | U8: =IF(R8=0,0,IF((1-Assumptions!$E$18)=1,R8,(1-Assumptions!$E$18)*(1-(1-Assumptions!$E$18)^R8)/(1-(1-Assumptions!$E$18)))) -> 6.992298
A9: 5 | B9: =IF($A9<=Assumptions!$C$20,Assumptions!$C$6*Assumptions!$C$9*Assumptions!$C$8,0) -> 52.5 | C9: =IF($A9<=Assumptions!$C$20,Assumptions!$C$20-$A9+1,0) -> 8 | D9: =MAX(0,C9-Assumptions!$C$19) -> 7 | E9: =IF(C9=0,0,IF((1-Assumptions!$C$17)=1,C9,(1-Assumptions!$C$17)*(1-(1-Assumptions!$C$17)^C9)/(1-(1-Assumptions!$C$17)))) -> 6.3950118 | F9: =IF(D9=0,0,IF((1-Assumptions!$C$17)=1,D9,(1-Assumptions!$C$17)*(1-(1-Assumptions!$C$17)^D9)/(1-(1-Assumptions!$C$17)))) -> 5.7315914 | G9: =IF(D9=0,0,IF((1-Assumptions!$C$18)=1,D9,(1-Assumptions!$C$18)*(1-(1-Assumptions!$C$18)^D9)/(1-(1-Assumptions!$C$18)))) -> 5.9652605 | I9: =IF($A9<=Assumptions!$D$20,Assumptions!$D$6*Assumptions!$D$9*Assumptions!$D$8,0) -> 80 | J9: =IF($A9<=Assumptions!$D$20,Assumptions!$D$20-$A9+1,0) -> 8 | K9: =MAX(0,J9-Assumptions!$D$19) -> 7 | L9: =IF(J9=0,0,IF((1-Assumptions!$D$17)=1,J9,(1-Assumptions!$D$17)*(1-(1-Assumptions!$D$17)^J9)/(1-(1-Assumptions!$D$17)))) -> 6.3950118 | M9: =IF(K9=0,0,IF((1-Assumptions!$D$17)=1,K9,(1-Assumptions!$D$17)*(1-(1-Assumptions!$D$17)^K9)/(1-(1-Assumptions!$D$17)))) -> 5.7315914 | N9: =IF(K9=0,0,IF((1-Assumptions!$D$18)=1,K9,(1-Assumptions!$D$18)*(1-(1-Assumptions!$D$18)^K9)/(1-(1-Assumptions!$D$18)))) -> 6.0856813 | P9: =IF($A9<=Assumptions!$E$20,Assumptions!$E$6*Assumptions!$E$9*Assumptions!$E$8,0) -> 135 | Q9: =IF($A9<=Assumptions!$E$20,Assumptions!$E$20-$A9+1,0) -> 8 | R9: =MAX(0,Q9-Assumptions!$E$19) -> 7 | S9: =IF(Q9=0,0,IF((1-Assumptions!$E$17)=1,Q9,(1-Assumptions!$E$17)*(1-(1-Assumptions!$E$17)^Q9)/(1-(1-Assumptions!$E$17)))) -> 6.3950118 | T9: =IF(R9=0,0,IF((1-Assumptions!$E$17)=1,R9,(1-Assumptions!$E$17)*(1-(1-Assumptions!$E$17)^R9)/(1-(1-Assumptions!$E$17)))) -> 5.7315914 | U9: =IF(R9=0,0,IF((1-Assumptions!$E$18)=1,R9,(1-Assumptions!$E$18)*(1-(1-Assumptions!$E$18)^R9)/(1-(1-Assumptions!$E$18)))) -> 6.2085547
A10: 6 | B10: =IF($A10<=Assumptions!$C$20,Assumptions!$C$6*Assumptions!$C$9*Assumptions!$C$8,0) -> 52.5 | C10: =IF($A10<=Assumptions!$C$20,Assumptions!$C$20-$A10+1,0) -> 7 | D10: =MAX(0,C10-Assumptions!$C$19) -> 6 | E10: =IF(C10=0,0,IF((1-Assumptions!$C$17)=1,C10,(1-Assumptions!$C$17)*(1-(1-Assumptions!$C$17)^C10)/(1-(1-Assumptions!$C$17)))) -> 5.7315914 | F10: =IF(D10=0,0,IF((1-Assumptions!$C$17)=1,D10,(1-Assumptions!$C$17)*(1-(1-Assumptions!$C$17)^D10)/(1-(1-Assumptions!$C$17)))) -> 5.0332541 | G10: =IF(D10=0,0,IF((1-Assumptions!$C$18)=1,D10,(1-Assumptions!$C$18)*(1-(1-Assumptions!$C$18)^D10)/(1-(1-Assumptions!$C$18)))) -> 5.213813 | I10: =IF($A10<=Assumptions!$D$20,Assumptions!$D$6*Assumptions!$D$9*Assumptions!$D$8,0) -> 80 | J10: =IF($A10<=Assumptions!$D$20,Assumptions!$D$20-$A10+1,0) -> 7 | K10: =MAX(0,J10-Assumptions!$D$19) -> 6 | L10: =IF(J10=0,0,IF((1-Assumptions!$D$17)=1,J10,(1-Assumptions!$D$17)*(1-(1-Assumptions!$D$17)^J10)/(1-(1-Assumptions!$D$17)))) -> 5.7315914 | M10: =IF(K10=0,0,IF((1-Assumptions!$D$17)=1,K10,(1-Assumptions!$D$17)*(1-(1-Assumptions!$D$17)^K10)/(1-(1-Assumptions!$D$17)))) -> 5.0332541 | N10: =IF(K10=0,0,IF((1-Assumptions!$D$18)=1,K10,(1-Assumptions!$D$18)*(1-(1-Assumptions!$D$18)^K10)/(1-(1-Assumptions!$D$18)))) -> 5.3064055 | P10: =IF($A10<=Assumptions!$E$20,Assumptions!$E$6*Assumptions!$E$9*Assumptions!$E$8,0) -> 135 | Q10: =IF($A10<=Assumptions!$E$20,Assumptions!$E$20-$A10+1,0) -> 7 | R10: =MAX(0,Q10-Assumptions!$E$19) -> 6 | S10: =IF(Q10=0,0,IF((1-Assumptions!$E$17)=1,Q10,(1-Assumptions!$E$17)*(1-(1-Assumptions!$E$17)^Q10)/(1-(1-Assumptions!$E$17)))) -> 5.7315914 | T10: =IF(R10=0,0,IF((1-Assumptions!$E$17)=1,R10,(1-Assumptions!$E$17)*(1-(1-Assumptions!$E$17)^R10)/(1-(1-Assumptions!$E$17)))) -> 5.0332541 | U10: =IF(R10=0,0,IF((1-Assumptions!$E$18)=1,R10,(1-Assumptions!$E$18)*(1-(1-Assumptions!$E$18)^R10)/(1-(1-Assumptions!$E$18)))) -> 5.4005718
A11: 7 | B11: =IF($A11<=Assumptions!$C$20,Assumptions!$C$6*Assumptions!$C$9*Assumptions!$C$8,0) -> 52.5 | C11: =IF($A11<=Assumptions!$C$20,Assumptions!$C$20-$A11+1,0) -> 6 | D11: =MAX(0,C11-Assumptions!$C$19) -> 5 | E11: =IF(C11=0,0,IF((1-Assumptions!$C$17)=1,C11,(1-Assumptions!$C$17)*(1-(1-Assumptions!$C$17)^C11)/(1-(1-Assumptions!$C$17)))) -> 5.0332541 | F11: =IF(D11=0,0,IF((1-Assumptions!$C$17)=1,D11,(1-Assumptions!$C$17)*(1-(1-Assumptions!$C$17)^D11)/(1-(1-Assumptions!$C$17)))) -> 4.2981622 | G11: =IF(D11=0,0,IF((1-Assumptions!$C$18)=1,D11,(1-Assumptions!$C$18)*(1-(1-Assumptions!$C$18)^D11)/(1-(1-Assumptions!$C$18)))) -> 4.4310553 | I11: =IF($A11<=Assumptions!$D$20,Assumptions!$D$6*Assumptions!$D$9*Assumptions!$D$8,0) -> 80 | J11: =IF($A11<=Assumptions!$D$20,Assumptions!$D$20-$A11+1,0) -> 6 | K11: =MAX(0,J11-Assumptions!$D$19) -> 5 | L11: =IF(J11=0,0,IF((1-Assumptions!$D$17)=1,J11,(1-Assumptions!$D$17)*(1-(1-Assumptions!$D$17)^J11)/(1-(1-Assumptions!$D$17)))) -> 5.0332541 | M11: =IF(K11=0,0,IF((1-Assumptions!$D$17)=1,K11,(1-Assumptions!$D$17)*(1-(1-Assumptions!$D$17)^K11)/(1-(1-Assumptions!$D$17)))) -> 4.2981622 | N11: =IF(K11=0,0,IF((1-Assumptions!$D$18)=1,K11,(1-Assumptions!$D$18)*(1-(1-Assumptions!$D$18)^K11)/(1-(1-Assumptions!$D$18)))) -> 4.4988658 | P11: =IF($A11<=Assumptions!$E$20,Assumptions!$E$6*Assumptions!$E$9*Assumptions!$E$8,0) -> 135 | Q11: =IF($A11<=Assumptions!$E$20,Assumptions!$E$20-$A11+1,0) -> 6 | R11: =MAX(0,Q11-Assumptions!$E$19) -> 5 | S11: =IF(Q11=0,0,IF((1-Assumptions!$E$17)=1,Q11,(1-Assumptions!$E$17)*(1-(1-Assumptions!$E$17)^Q11)/(1-(1-Assumptions!$E$17)))) -> 5.0332541 | T11: =IF(R11=0,0,IF((1-Assumptions!$E$17)=1,R11,(1-Assumptions!$E$17)*(1-(1-Assumptions!$E$17)^R11)/(1-(1-Assumptions!$E$17)))) -> 4.2981622 | U11: =IF(R11=0,0,IF((1-Assumptions!$E$18)=1,R11,(1-Assumptions!$E$18)*(1-(1-Assumptions!$E$18)^R11)/(1-(1-Assumptions!$E$18)))) -> 4.5675998
A12: 8 | B12: =IF($A12<=Assumptions!$C$20,Assumptions!$C$6*Assumptions!$C$9*Assumptions!$C$8,0) -> 52.5 | C12: =IF($A12<=Assumptions!$C$20,Assumptions!$C$20-$A12+1,0) -> 5 | D12: =MAX(0,C12-Assumptions!$C$19) -> 4 | E12: =IF(C12=0,0,IF((1-Assumptions!$C$17)=1,C12,(1-Assumptions!$C$17)*(1-(1-Assumptions!$C$17)^C12)/(1-(1-Assumptions!$C$17)))) -> 4.2981622 | F12: =IF(D12=0,0,IF((1-Assumptions!$C$17)=1,D12,(1-Assumptions!$C$17)*(1-(1-Assumptions!$C$17)^D12)/(1-(1-Assumptions!$C$17)))) -> 3.5243812 | G12: =IF(D12=0,0,IF((1-Assumptions!$C$18)=1,D12,(1-Assumptions!$C$18)*(1-(1-Assumptions!$C$18)^D12)/(1-(1-Assumptions!$C$18)))) -> 3.6156826 | I12: =IF($A12<=Assumptions!$D$20,Assumptions!$D$6*Assumptions!$D$9*Assumptions!$D$8,0) -> 80 | J12: =IF($A12<=Assumptions!$D$20,Assumptions!$D$20-$A12+1,0) -> 5 | K12: =MAX(0,J12-Assumptions!$D$19) -> 4 | L12: =IF(J12=0,0,IF((1-Assumptions!$D$17)=1,J12,(1-Assumptions!$D$17)*(1-(1-Assumptions!$D$17)^J12)/(1-(1-Assumptions!$D$17)))) -> 4.2981622 | M12: =IF(K12=0,0,IF((1-Assumptions!$D$17)=1,K12,(1-Assumptions!$D$17)*(1-(1-Assumptions!$D$17)^K12)/(1-(1-Assumptions!$D$17)))) -> 3.5243812 | N12: =IF(K12=0,0,IF((1-Assumptions!$D$18)=1,K12,(1-Assumptions!$D$18)*(1-(1-Assumptions!$D$18)^K12)/(1-(1-Assumptions!$D$18)))) -> 3.6620371 | P12: =IF($A12<=Assumptions!$E$20,Assumptions!$E$6*Assumptions!$E$9*Assumptions!$E$8,0) -> 135 | Q12: =IF($A12<=Assumptions!$E$20,Assumptions!$E$20-$A12+1,0) -> 5 | R12: =MAX(0,Q12-Assumptions!$E$19) -> 4 | S12: =IF(Q12=0,0,IF((1-Assumptions!$E$17)=1,Q12,(1-Assumptions!$E$17)*(1-(1-Assumptions!$E$17)^Q12)/(1-(1-Assumptions!$E$17)))) -> 4.2981622 | T12: =IF(R12=0,0,IF((1-Assumptions!$E$17)=1,R12,(1-Assumptions!$E$17)*(1-(1-Assumptions!$E$17)^R12)/(1-(1-Assumptions!$E$17)))) -> 3.5243812 | U12: =IF(R12=0,0,IF((1-Assumptions!$E$18)=1,R12,(1-Assumptions!$E$18)*(1-(1-Assumptions!$E$18)^R12)/(1-(1-Assumptions!$E$18)))) -> 3.7088658
A13: 9 | B13: =IF($A13<=Assumptions!$C$20,Assumptions!$C$6*Assumptions!$C$9*Assumptions!$C$8,0) -> 52.5 | C13: =IF($A13<=Assumptions!$C$20,Assumptions!$C$20-$A13+1,0) -> 4 | D13: =MAX(0,C13-Assumptions!$C$19) -> 3 | E13: =IF(C13=0,0,IF((1-Assumptions!$C$17)=1,C13,(1-Assumptions!$C$17)*(1-(1-Assumptions!$C$17)^C13)/(1-(1-Assumptions!$C$17)))) -> 3.5243812 | F13: =IF(D13=0,0,IF((1-Assumptions!$C$17)=1,D13,(1-Assumptions!$C$17)*(1-(1-Assumptions!$C$17)^D13)/(1-(1-Assumptions!$C$17)))) -> 2.709875 | G13: =IF(D13=0,0,IF((1-Assumptions!$C$18)=1,D13,(1-Assumptions!$C$18)*(1-(1-Assumptions!$C$18)^D13)/(1-(1-Assumptions!$C$18)))) -> 2.766336 | I13: =IF($A13<=Assumptions!$D$20,Assumptions!$D$6*Assumptions!$D$9*Assumptions!$D$8,0) -> 80 | J13: =IF($A13<=Assumptions!$D$20,Assumptions!$D$20-$A13+1,0) -> 4 | K13: =MAX(0,J13-Assumptions!$D$19) -> 3 | L13: =IF(J13=0,0,IF((1-Assumptions!$D$17)=1,J13,(1-Assumptions!$D$17)*(1-(1-Assumptions!$D$17)^J13)/(1-(1-Assumptions!$D$17)))) -> 3.5243812 | M13: =IF(K13=0,0,IF((1-Assumptions!$D$17)=1,K13,(1-Assumptions!$D$17)*(1-(1-Assumptions!$D$17)^K13)/(1-(1-Assumptions!$D$17)))) -> 2.709875 | N13: =IF(K13=0,0,IF((1-Assumptions!$D$18)=1,K13,(1-Assumptions!$D$18)*(1-(1-Assumptions!$D$18)^K13)/(1-(1-Assumptions!$D$18)))) -> 2.7948571 | P13: =IF($A13<=Assumptions!$E$20,Assumptions!$E$6*Assumptions!$E$9*Assumptions!$E$8,0) -> 135 | Q13: =IF($A13<=Assumptions!$E$20,Assumptions!$E$20-$A13+1,0) -> 4 | R13: =MAX(0,Q13-Assumptions!$E$19) -> 3 | S13: =IF(Q13=0,0,IF((1-Assumptions!$E$17)=1,Q13,(1-Assumptions!$E$17)*(1-(1-Assumptions!$E$17)^Q13)/(1-(1-Assumptions!$E$17)))) -> 3.5243812 | T13: =IF(R13=0,0,IF((1-Assumptions!$E$17)=1,R13,(1-Assumptions!$E$17)*(1-(1-Assumptions!$E$17)^R13)/(1-(1-Assumptions!$E$17)))) -> 2.709875 | U13: =IF(R13=0,0,IF((1-Assumptions!$E$18)=1,R13,(1-Assumptions!$E$18)*(1-(1-Assumptions!$E$18)^R13)/(1-(1-Assumptions!$E$18)))) -> 2.823573
A14: 10 | B14: =IF($A14<=Assumptions!$C$20,Assumptions!$C$6*Assumptions!$C$9*Assumptions!$C$8,0) -> 52.5 | C14: =IF($A14<=Assumptions!$C$20,Assumptions!$C$20-$A14+1,0) -> 3 | D14: =MAX(0,C14-Assumptions!$C$19) -> 2 | E14: =IF(C14=0,0,IF((1-Assumptions!$C$17)=1,C14,(1-Assumptions!$C$17)*(1-(1-Assumptions!$C$17)^C14)/(1-(1-Assumptions!$C$17)))) -> 2.709875 | F14: =IF(D14=0,0,IF((1-Assumptions!$C$17)=1,D14,(1-Assumptions!$C$17)*(1-(1-Assumptions!$C$17)^D14)/(1-(1-Assumptions!$C$17)))) -> 1.8525 | G14: =IF(D14=0,0,IF((1-Assumptions!$C$18)=1,D14,(1-Assumptions!$C$18)*(1-(1-Assumptions!$C$18)^D14)/(1-(1-Assumptions!$C$18)))) -> 1.8816 | I14: =IF($A14<=Assumptions!$D$20,Assumptions!$D$6*Assumptions!$D$9*Assumptions!$D$8,0) -> 80 | J14: =IF($A14<=Assumptions!$D$20,Assumptions!$D$20-$A14+1,0) -> 3 | K14: =MAX(0,J14-Assumptions!$D$19) -> 2 | L14: =IF(J14=0,0,IF((1-Assumptions!$D$17)=1,J14,(1-Assumptions!$D$17)*(1-(1-Assumptions!$D$17)^J14)/(1-(1-Assumptions!$D$17)))) -> 2.709875 | M14: =IF(K14=0,0,IF((1-Assumptions!$D$17)=1,K14,(1-Assumptions!$D$17)*(1-(1-Assumptions!$D$17)^K14)/(1-(1-Assumptions!$D$17)))) -> 1.8525 | N14: =IF(K14=0,0,IF((1-Assumptions!$D$18)=1,K14,(1-Assumptions!$D$18)*(1-(1-Assumptions!$D$18)^K14)/(1-(1-Assumptions!$D$18)))) -> 1.896225 | P14: =IF($A14<=Assumptions!$E$20,Assumptions!$E$6*Assumptions!$E$9*Assumptions!$E$8,0) -> 135 | Q14: =IF($A14<=Assumptions!$E$20,Assumptions!$E$20-$A14+1,0) -> 3 | R14: =MAX(0,Q14-Assumptions!$E$19) -> 2 | S14: =IF(Q14=0,0,IF((1-Assumptions!$E$17)=1,Q14,(1-Assumptions!$E$17)*(1-(1-Assumptions!$E$17)^Q14)/(1-(1-Assumptions!$E$17)))) -> 2.709875 | T14: =IF(R14=0,0,IF((1-Assumptions!$E$17)=1,R14,(1-Assumptions!$E$17)*(1-(1-Assumptions!$E$17)^R14)/(1-(1-Assumptions!$E$17)))) -> 1.8525 | U14: =IF(R14=0,0,IF((1-Assumptions!$E$18)=1,R14,(1-Assumptions!$E$18)*(1-(1-Assumptions!$E$18)^R14)/(1-(1-Assumptions!$E$18)))) -> 1.9109
A15: 11 | B15: =IF($A15<=Assumptions!$C$20,Assumptions!$C$6*Assumptions!$C$9*Assumptions!$C$8,0) -> 52.5 | C15: =IF($A15<=Assumptions!$C$20,Assumptions!$C$20-$A15+1,0) -> 2 | D15: =MAX(0,C15-Assumptions!$C$19) -> 1 | E15: =IF(C15=0,0,IF((1-Assumptions!$C$17)=1,C15,(1-Assumptions!$C$17)*(1-(1-Assumptions!$C$17)^C15)/(1-(1-Assumptions!$C$17)))) -> 1.8525 | F15: =IF(D15=0,0,IF((1-Assumptions!$C$17)=1,D15,(1-Assumptions!$C$17)*(1-(1-Assumptions!$C$17)^D15)/(1-(1-Assumptions!$C$17)))) -> 0.95 | G15: =IF(D15=0,0,IF((1-Assumptions!$C$18)=1,D15,(1-Assumptions!$C$18)*(1-(1-Assumptions!$C$18)^D15)/(1-(1-Assumptions!$C$18)))) -> 0.96 | I15: =IF($A15<=Assumptions!$D$20,Assumptions!$D$6*Assumptions!$D$9*Assumptions!$D$8,0) -> 80 | J15: =IF($A15<=Assumptions!$D$20,Assumptions!$D$20-$A15+1,0) -> 2 | K15: =MAX(0,J15-Assumptions!$D$19) -> 1 | L15: =IF(J15=0,0,IF((1-Assumptions!$D$17)=1,J15,(1-Assumptions!$D$17)*(1-(1-Assumptions!$D$17)^J15)/(1-(1-Assumptions!$D$17)))) -> 1.8525 | M15: =IF(K15=0,0,IF((1-Assumptions!$D$17)=1,K15,(1-Assumptions!$D$17)*(1-(1-Assumptions!$D$17)^K15)/(1-(1-Assumptions!$D$17)))) -> 0.95 | N15: =IF(K15=0,0,IF((1-Assumptions!$D$18)=1,K15,(1-Assumptions!$D$18)*(1-(1-Assumptions!$D$18)^K15)/(1-(1-Assumptions!$D$18)))) -> 0.965 | P15: =IF($A15<=Assumptions!$E$20,Assumptions!$E$6*Assumptions!$E$9*Assumptions!$E$8,0) -> 135 | Q15: =IF($A15<=Assumptions!$E$20,Assumptions!$E$20-$A15+1,0) -> 2 | R15: =MAX(0,Q15-Assumptions!$E$19) -> 1 | S15: =IF(Q15=0,0,IF((1-Assumptions!$E$17)=1,Q15,(1-Assumptions!$E$17)*(1-(1-Assumptions!$E$17)^Q15)/(1-(1-Assumptions!$E$17)))) -> 1.8525 | T15: =IF(R15=0,0,IF((1-Assumptions!$E$17)=1,R15,(1-Assumptions!$E$17)*(1-(1-Assumptions!$E$17)^R15)/(1-(1-Assumptions!$E$17)))) -> 0.95 | U15: =IF(R15=0,0,IF((1-Assumptions!$E$18)=1,R15,(1-Assumptions!$E$18)*(1-(1-Assumptions!$E$18)^R15)/(1-(1-Assumptions!$E$18)))) -> 0.97
A16: 12 | B16: =IF($A16<=Assumptions!$C$20,Assumptions!$C$6*Assumptions!$C$9*Assumptions!$C$8,0) -> 52.5 | C16: =IF($A16<=Assumptions!$C$20,Assumptions!$C$20-$A16+1,0) -> 1 | D16: =MAX(0,C16-Assumptions!$C$19) -> 0 | E16: =IF(C16=0,0,IF((1-Assumptions!$C$17)=1,C16,(1-Assumptions!$C$17)*(1-(1-Assumptions!$C$17)^C16)/(1-(1-Assumptions!$C$17)))) -> 0.95 | F16: =IF(D16=0,0,IF((1-Assumptions!$C$17)=1,D16,(1-Assumptions!$C$17)*(1-(1-Assumptions!$C$17)^D16)/(1-(1-Assumptions!$C$17)))) -> 0 | G16: =IF(D16=0,0,IF((1-Assumptions!$C$18)=1,D16,(1-Assumptions!$C$18)*(1-(1-Assumptions!$C$18)^D16)/(1-(1-Assumptions!$C$18)))) -> 0 | I16: =IF($A16<=Assumptions!$D$20,Assumptions!$D$6*Assumptions!$D$9*Assumptions!$D$8,0) -> 80 | J16: =IF($A16<=Assumptions!$D$20,Assumptions!$D$20-$A16+1,0) -> 1 | K16: =MAX(0,J16-Assumptions!$D$19) -> 0 | L16: =IF(J16=0,0,IF((1-Assumptions!$D$17)=1,J16,(1-Assumptions!$D$17)*(1-(1-Assumptions!$D$17)^J16)/(1-(1-Assumptions!$D$17)))) -> 0.95 | M16: =IF(K16=0,0,IF((1-Assumptions!$D$17)=1,K16,(1-Assumptions!$D$17)*(1-(1-Assumptions!$D$17)^K16)/(1-(1-Assumptions!$D$17)))) -> 0 | N16: =IF(K16=0,0,IF((1-Assumptions!$D$18)=1,K16,(1-Assumptions!$D$18)*(1-(1-Assumptions!$D$18)^K16)/(1-(1-Assumptions!$D$18)))) -> 0 | P16: =IF($A16<=Assumptions!$E$20,Assumptions!$E$6*Assumptions!$E$9*Assumptions!$E$8,0) -> 135 | Q16: =IF($A16<=Assumptions!$E$20,Assumptions!$E$20-$A16+1,0) -> 1 | R16: =MAX(0,Q16-Assumptions!$E$19) -> 0 | S16: =IF(Q16=0,0,IF((1-Assumptions!$E$17)=1,Q16,(1-Assumptions!$E$17)*(1-(1-Assumptions!$E$17)^Q16)/(1-(1-Assumptions!$E$17)))) -> 0.95 | T16: =IF(R16=0,0,IF((1-Assumptions!$E$17)=1,R16,(1-Assumptions!$E$17)*(1-(1-Assumptions!$E$17)^R16)/(1-(1-Assumptions!$E$17)))) -> 0 | U16: =IF(R16=0,0,IF((1-Assumptions!$E$18)=1,R16,(1-Assumptions!$E$18)*(1-(1-Assumptions!$E$18)^R16)/(1-(1-Assumptions!$E$18)))) -> 0
A17: 13 | B17: =IF($A17<=Assumptions!$C$20,Assumptions!$C$6*Assumptions!$C$9*Assumptions!$C$8,0) -> 0 | C17: =IF($A17<=Assumptions!$C$20,Assumptions!$C$20-$A17+1,0) -> 0 | D17: =MAX(0,C17-Assumptions!$C$19) -> 0 | E17: =IF(C17=0,0,IF((1-Assumptions!$C$17)=1,C17,(1-Assumptions!$C$17)*(1-(1-Assumptions!$C$17)^C17)/(1-(1-Assumptions!$C$17)))) -> 0 | F17: =IF(D17=0,0,IF((1-Assumptions!$C$17)=1,D17,(1-Assumptions!$C$17)*(1-(1-Assumptions!$C$17)^D17)/(1-(1-Assumptions!$C$17)))) -> 0 | G17: =IF(D17=0,0,IF((1-Assumptions!$C$18)=1,D17,(1-Assumptions!$C$18)*(1-(1-Assumptions!$C$18)^D17)/(1-(1-Assumptions!$C$18)))) -> 0 | I17: =IF($A17<=Assumptions!$D$20,Assumptions!$D$6*Assumptions!$D$9*Assumptions!$D$8,0) -> 0 | J17: =IF($A17<=Assumptions!$D$20,Assumptions!$D$20-$A17+1,0) -> 0 | K17: =MAX(0,J17-Assumptions!$D$19) -> 0 | L17: =IF(J17=0,0,IF((1-Assumptions!$D$17)=1,J17,(1-Assumptions!$D$17)*(1-(1-Assumptions!$D$17)^J17)/(1-(1-Assumptions!$D$17)))) -> 0 | M17: =IF(K17=0,0,IF((1-Assumptions!$D$17)=1,K17,(1-Assumptions!$D$17)*(1-(1-Assumptions!$D$17)^K17)/(1-(1-Assumptions!$D$17)))) -> 0 | N17: =IF(K17=0,0,IF((1-Assumptions!$D$18)=1,K17,(1-Assumptions!$D$18)*(1-(1-Assumptions!$D$18)^K17)/(1-(1-Assumptions!$D$18)))) -> 0 | P17: =IF($A17<=Assumptions!$E$20,Assumptions!$E$6*Assumptions!$E$9*Assumptions!$E$8,0) -> 0 | Q17: =IF($A17<=Assumptions!$E$20,Assumptions!$E$20-$A17+1,0) -> 0 | R17: =MAX(0,Q17-Assumptions!$E$19) -> 0 | S17: =IF(Q17=0,0,IF((1-Assumptions!$E$17)=1,Q17,(1-Assumptions!$E$17)*(1-(1-Assumptions!$E$17)^Q17)/(1-(1-Assumptions!$E$17)))) -> 0 | T17: =IF(R17=0,0,IF((1-Assumptions!$E$17)=1,R17,(1-Assumptions!$E$17)*(1-(1-Assumptions!$E$17)^R17)/(1-(1-Assumptions!$E$17)))) -> 0 | U17: =IF(R17=0,0,IF((1-Assumptions!$E$18)=1,R17,(1-Assumptions!$E$18)*(1-(1-Assumptions!$E$18)^R17)/(1-(1-Assumptions!$E$18)))) -> 0
... A28: 24 | B28: =IF($A28<=Assumptions!$C$20,Assumptions!$C$6*Assumptions!$C$9*Assumptions!$C$8,0) -> 0 | C28: =IF($A28<=Assumptions!$C$20,Assumptions!$C$20-$A28+1,0) -> 0 | D28: =MAX(0,C28-Assumptions!$C$19) -> 0 | E28: =IF(C28=0,0,IF((1-Assumptions!$C$17)=1,C28,(1-Assumptions!$C$17)*(1-(1-Assumptions!$C$17)^C28)/(1-(1-Assumptions!$C$17)))) -> 0 | F28: =IF(D28=0,0,IF((1-Assumptions!$C$17)=1,D28,(1-Assumptions!$C$17)*(1-(1-Assumptions!$C$17)^D28)/(1-(1-Assumptions!$C$17)))) -> 0 | G28: =IF(D28=0,0,IF((1-Assumptions!$C$18)=1,D28,(1-Assumptions!$C$18)*(1-(1-Assumptions!$C$18)^D28)/(1-(1-Assumptions!$C$18)))) -> 0 | I28: =IF($A28<=Assumptions!$D$20,Assumptions!$D$6*Assumptions!$D$9*Assumptions!$D$8,0) -> 0 | J28: =IF($A28<=Assumptions!$D$20,Assumptions!$D$20-$A28+1,0) -> 0 | K28: =MAX(0,J28-Assumptions!$D$19) -> 0 | L28: =IF(J28=0,0,IF((1-Assumptions!$D$17)=1,J28,(1-Assumptions!$D$17)*(1-(1-Assumptions!$D$17)^J28)/(1-(1-Assumptions!$D$17)))) -> 0 | M28: =IF(K28=0,0,IF((1-Assumptions!$D$17)=1,K28,(1-Assumptions!$D$17)*(1-(1-Assumptions!$D$17)^K28)/(1-(1-Assumptions!$D$17)))) -> 0 | N28: =IF(K28=0,0,IF((1-Assumptions!$D$18)=1,K28,(1-Assumptions!$D$18)*(1-(1-Assumptions!$D$18)^K28)/(1-(1-Assumptions!$D$18)))) -> 0 | P28: =IF($A28<=Assumptions!$E$20,Assumptions!$E$6*Assumptions!$E$9*Assumptions!$E$8,0) -> 0 | Q28: =IF($A28<=Assumptions!$E$20,Assumptions!$E$20-$A28+1,0) -> 0 | R28: =MAX(0,Q28-Assumptions!$E$19) -> 0 | S28: =IF(Q28=0,0,IF((1-Assumptions!$E$17)=1,Q28,(1-Assumptions!$E$17)*(1-(1-Assumptions!$E$17)^Q28)/(1-(1-Assumptions!$E$17)))) -> 0 | T28: =IF(R28=0,0,IF((1-Assumptions!$E$17)=1,R28,(1-Assumptions!$E$17)*(1-(1-Assumptions!$E$17)^R28)/(1-(1-Assumptions!$E$17)))) -> 0 | U28: =IF(R28=0,0,IF((1-Assumptions!$E$18)=1,R28,(1-Assumptions!$E$18)*(1-(1-Assumptions!$E$18)^R28)/(1-(1-Assumptions!$E$18)))) -> 0
A30: Summary by scenario | B30: Unit | C30: Conservative | D30: Base | E30: Optimistic
A31: S1 exposed accounts (launch cohort only) | B31: accounts | C31: =B5 -> 1050 | D31: =I5 -> 1600 | E31: =P5 -> 2250
A32: S1 sum of size x control retained months (L) | B32: account-months | C32: =B5*E5 -> 9169.8163 | D32: =I5*L5 -> 13973.053 | E32: =P5*S5 -> 19649.606
A33: S1 sum of size x (activator - control retained months, benefit months) | B33: account-months | C33: =B5*(G5-F5) -> 513.93071 | D33: =I5*(N5-M5) -> 1194.592 | E33: =P5*(U5-T5) -> 2278.0269
A34: S2 total exposed accounts over the window | B34: accounts | C34: =SUM(B5:B28) -> 1627.5 | D34: =SUM(I5:I28) -> 2480 | E34: =SUM(P5:P28) -> 3735
A35: S2 sum of size x control retained months (L) | B35: account-months | C35: =SUMPRODUCT(B5:B28,E5:E28) -> 11970 | D35: =SUMPRODUCT(I5:I28,L5:L28) -> 18240 | E35: =SUMPRODUCT(P5:P28,S5:S28) -> 26850.079
A36: S2 sum of size x (activator - control retained months, benefit months) | B36: account-months | C36: =SUMPRODUCT(B5:B28,G5:G28)-SUMPRODUCT(B5:B28,F5:F28) -> 608.40778 | D36: =SUMPRODUCT(I5:I28,N5:N28)-SUMPRODUCT(I5:I28,M5:M28) -> 1412.9703 | E36: =SUMPRODUCT(P5:P28,U5:U28)-SUMPRODUCT(P5:P28,T5:T28) -> 2774.9363
A37: Horizon within 24-month capacity? | B37: check | C37: =IF(Assumptions!$C$20<=24,"OK","INCREASE TABLE") -> OK | D37: =IF(Assumptions!$D$20<=24,"OK","INCREASE TABLE") -> OK | E37: =IF(Assumptions!$E$20<=24,"OK","INCREASE TABLE") -> OK

Sheet Revenue and business case
A1: Revenue and business case: two views over the same horizon and cost basis
A3: Item | B3: Unit | C3: Conservative | D3: Base | E3: Optimistic | F3: Logic
A4: Common drivers
A5: Incremental activation rate (treatment minus control) | B5: % of exposed | C5: ='Adoption funnel'!C10-Assumptions!$C$15 -> 0.0225 | D5: ='Adoption funnel'!D10-Assumptions!$D$15 -> 0.07852 | E5: ='Adoption funnel'!E10-Assumptions!$E$15 -> 0.1364 | F5: end-to-end activation - control activation
A6: Monthly churn, control | B6: % per month | C6: =Assumptions!$C$17 -> 0.05 | D6: =Assumptions!$D$17 -> 0.05 | E6: =Assumptions!$E$17 -> 0.05 | F6: assumption
A7: Monthly churn, incremental activators | B7: % per month | C7: =Assumptions!$C$18 -> 0.04 | D7: =Assumptions!$D$18 -> 0.035 | E7: =Assumptions!$E$18 -> 0.03 | F7: assumption
A8: Churn reduction for an incremental activator | B8: pp per month | C8: =C6-C7 -> 0.01 | D8: =D6-D7 -> 0.015 | E8: =E6-E7 -> 0.02 | F8: control - activator
A9: Activation lag before benefit | B9: months | C9: =Assumptions!$C$19 -> 1 | D9: =Assumptions!$D$19 -> 1 | E9: =Assumptions!$E$19 -> 1 | F9: assumption
A10: Horizon | B10: months | C10: =Assumptions!$C$20 -> 12 | D10: =Assumptions!$D$20 -> 12 | E10: =Assumptions!$E$20 -> 12 | F10: assumption
A11: Average monthly plan price | B11: INR / account / month | C11: =Assumptions!$C$22 -> 2500 | D11: =Assumptions!$D$22 -> 2500 | E11: =Assumptions!$E$22 -> 2500 | F11: placeholder
A12: Gross margin on plan revenue | B12: % | C12: =Assumptions!$C$23 -> 0.85 | D12: =Assumptions!$D$23 -> 0.85 | E12: =Assumptions!$E$23 -> 0.85 | F12: placeholder
A13: Expected treatment-minus-holdout survival gap at horizon end (launch cohort) | B13: percentage points | C13: =C5*((1-C7)^MAX(0,C10-C9)-(1-C6)^MAX(0,C10-C9)) -> 0.0015623829 | D13: =D5*((1-D7)^MAX(0,D10-D9)-(1-D6)^MAX(0,D10-D9)) -> 0.0083994652 | E13: =E5*((1-E7)^MAX(0,E10-E9)-(1-E6)^MAX(0,E10-E9)) -> 0.019982779 | F13: what a holdout would need to detect; small gaps need large samples
A14: Monthly plan revenue of the existing base (context only; NOT credited to the programme) | B14: INR / month | C14: =Assumptions!$C$6*Assumptions!$C$22 -> 12500000 | D14: =Assumptions!$D$6*Assumptions!$D$22 -> 12500000 | E14: =Assumptions!$E$6*Assumptions!$E$22 -> 12500000 | F14: active x price
A16: Scenario 1: single cohort. The existing eligible base is exposed once; no later cohorts; full programme cost for the whole horizon
A17: Exposed accounts (launch cohort) | B17: accounts | C17: ='Cohort engine'!C31 -> 1050 | D17: ='Cohort engine'!D31 -> 1600 | E17: ='Cohort engine'!E31 -> 2250 | F17: Cohort engine
A18: Incremental activations | B18: accounts | C18: =C17*C5 -> 23.625 | D18: =D17*D5 -> 125.632 | E18: =E17*E5 -> 306.9 | F18: exposed x incremental rate
A19: Incremental retained account-months | B19: account-months | C19: =C5*'Cohort engine'!C33 -> 11.563441 | D19: =D5*'Cohort engine'!D33 -> 93.799366 | E19: =E5*'Cohort engine'!E33 -> 310.72287 | F19: rate x sum of size x (activator - control months)
A20: Incremental plan revenue | B20: INR | C20: =C19*C11 -> 28908.602 | D20: =D19*D11 -> 234498.42 | E20: =E19*E11 -> 776807.16 | F20: account-months x price
A21: Gross profit on incremental revenue | B21: INR | C21: =C20*C12 -> 24572.312 | D21: =D20*D12 -> 199323.65 | E21: =E20*E12 -> 660286.09 | F21: revenue x gross margin
A22: Programme cost over horizon | B22: INR | C22: ='Cost model'!C9*C10+'Cohort engine'!C31*Assumptions!$C$10*Assumptions!$C$31*Assumptions!$C$30*'Cost model'!C11 -> 444000 | D22: ='Cost model'!D9*D10+'Cohort engine'!D31*Assumptions!$D$10*Assumptions!$D$31*Assumptions!$D$30*'Cost model'!D11 -> 444000 | E22: ='Cost model'!E9*E10+'Cohort engine'!E31*Assumptions!$E$10*Assumptions!$E$31*Assumptions!$E$30*'Cost model'!E11 -> 444000 | F22: fixed x H + AI token cost on cohort impressions (0 while AI is off)
A23: Net contribution over horizon | B23: INR | C23: =C21-C22 -> -419427.69 | D23: =D21-D22 -> -244676.35 | E23: =E21-E22 -> 216286.09 | F23: gross profit - programme cost
A24: Average net contribution per month | B24: INR / month | C24: =C23/C10 -> -34952.307 | D24: =D23/D10 -> -20389.696 | E24: =E23/E10 -> 18023.841 | F24: net / H
A25: ROI on programme cost | B25: % | C25: =IF(C22=0,0,C23/C22) -> -0.94465695 | D25: =IF(D22=0,0,D23/D22) -> -0.55107285 | E25: =IF(E22=0,0,E23/E22) -> 0.48713083 | F25: net contribution / programme cost
A26: Break-even incremental account-months | B26: account-months | C26: =IF(C11*C12=0,0,C22/(C11*C12)) -> 208.94118 | D26: =IF(D11*D12=0,0,D22/(D11*D12)) -> 208.94118 | E26: =IF(E11*E12=0,0,E22/(E11*E12)) -> 208.94118 | F26: cost / (price x gross margin)
A27: Modelled account-months as a multiple of break-even | B27: x | C27: =IF(C26=0,0,C19/C26) -> 0.055343045 | D27: =IF(D26=0,0,D19/D26) -> 0.44892715 | E27: =IF(E26=0,0,E19/E26) -> 1.4871308 | F27: >=1.00x pays back
A28: Programme cost per incremental retained account-month | B28: INR | C28: =IF(C19<=0,0,C22/C19) -> 38396.875 | D28: =IF(D19<=0,0,D22/D19) -> 4733.5075 | E28: =IF(E19<=0,0,E22/E19) -> 1428.9261 | F28: cost / incremental account-months (compare with price x margin)
A30: Scenario 2: recurring monthly rollout. Launch cohort PLUS a new cohort each month; same horizon and same cost lines; includes Scenario 1
A31: Launch cohort exposed | B31: accounts | C31: ='Cohort engine'!C31 -> 1050 | D31: ='Cohort engine'!D31 -> 1600 | E31: ='Cohort engine'!E31 -> 2250 | F31: Cohort engine
A32: New cohort exposed each month after launch | B32: accounts / month | C32: =Assumptions!$C$6*Assumptions!$C$9*Assumptions!$C$8 -> 52.5 | D32: =Assumptions!$D$6*Assumptions!$D$9*Assumptions!$D$8 -> 80 | E32: =Assumptions!$E$6*Assumptions!$E$9*Assumptions!$E$8 -> 135 | F32: active x newly eligible share x exposure rate
A33: Total exposed accounts over the horizon | B33: accounts | C33: ='Cohort engine'!C34 -> 1627.5 | D33: ='Cohort engine'!D34 -> 2480 | E33: ='Cohort engine'!E34 -> 3735 | F33: Cohort engine
A34: Incremental activations | B34: accounts | C34: =C33*C5 -> 36.61875 | D34: =D33*D5 -> 194.7296 | E34: =E33*E5 -> 509.454 | F34: exposed x incremental rate
A35: Incremental retained account-months (within horizon) | B35: account-months | C35: =C5*'Cohort engine'!C36 -> 13.689175 | D35: =D5*'Cohort engine'!D36 -> 110.94643 | E35: =E5*'Cohort engine'!E36 -> 378.50131 | F35: later cohorts have fewer months left in the window
A36: Incremental plan revenue | B36: INR | C36: =C35*C11 -> 34222.938 | D36: =D35*D11 -> 277366.08 | E36: =E35*E11 -> 946253.27 | F36: account-months x price
A37: Gross profit on incremental revenue | B37: INR | C37: =C36*C12 -> 29089.497 | D37: =D36*D12 -> 235761.16 | E37: =E36*E12 -> 804315.28 | F37: revenue x gross margin
A38: Programme cost over horizon | B38: INR | C38: ='Cost model'!C9*C10+'Cohort engine'!C34*Assumptions!$C$10*Assumptions!$C$31*Assumptions!$C$30*'Cost model'!C11 -> 444000 | D38: ='Cost model'!D9*D10+'Cohort engine'!D34*Assumptions!$D$10*Assumptions!$D$31*Assumptions!$D$30*'Cost model'!D11 -> 444000 | E38: ='Cost model'!E9*E10+'Cohort engine'!E34*Assumptions!$E$10*Assumptions!$E$31*Assumptions!$E$30*'Cost model'!E11 -> 444000 | F38: fixed x H + AI token cost on all cohort impressions
A39: Net contribution over horizon | B39: INR | C39: =C37-C38 -> -414910.5 | D39: =D37-D38 -> -208238.84 | E39: =E37-E38 -> 360315.28 | F39: gross profit - programme cost
A40: Average net contribution per month | B40: INR / month | C40: =C39/C10 -> -34575.875 | D40: =D39/D10 -> -17353.236 | E40: =E39/E10 -> 30026.274 | F40: net / H
A41: ROI on programme cost | B41: % | C41: =IF(C38=0,0,C39/C38) -> -0.93448311 | D41: =IF(D38=0,0,D39/D38) -> -0.46900639 | E41: =IF(E38=0,0,E39/E38) -> 0.81152091 | F41: net contribution / programme cost
A42: Break-even incremental account-months | B42: account-months | C42: =IF(C11*C12=0,0,C38/(C11*C12)) -> 208.94118 | D42: =IF(D11*D12=0,0,D38/(D11*D12)) -> 208.94118 | E42: =IF(E11*E12=0,0,E38/(E11*E12)) -> 208.94118 | F42: cost / (price x gross margin)
A43: Modelled account-months as a multiple of break-even | B43: x | C43: =IF(C42=0,0,C35/C42) -> 0.065516885 | D43: =IF(D42=0,0,D35/D42) -> 0.53099361 | E43: =IF(E42=0,0,E35/E42) -> 1.8115209 | F43: >=1.00x pays back
...

Sheet Billing and audit
A1: Pricing options and monthly audit (Base scenario; every option uses the same horizon and the same cost basis)
A4: Scenario 1 (single cohort), Base inputs
A5: Item | B5: Unit | C5: A: Free for all eligible | D5: B: Higher plan only | E5: C: Paid add-on | F5: Logic
A6: Adoption factor vs free version | B6: x | C6: =1 -> 1 | D6: =Assumptions!$D$38 -> 0.2 | E6: =Assumptions!$D$43 -> 0.4 | F6: A: 100%. B: only accounts already on the higher plan see it. C: guessed share surviving a paywall
A7: Incremental retained account-months from discovery | B7: account-months | C7: ='Revenue and business case'!$D$19*C6 -> 93.799366 | D7: ='Revenue and business case'!$D$19*D6 -> 18.759873 | E7: ='Revenue and business case'!$D$19*E6 -> 37.519746 | F7: scenario account-months x factor
A8: Plan revenue from the retention effect | B8: INR | C8: =C7*Assumptions!$D$22 -> 234498.42 | D8: =D7*Assumptions!$D$22 -> 46899.683 | E8: =E7*Assumptions!$D$22 -> 93799.366 | F8: account-months x price
A9: Billed account-months of the paid feature | B9: account-months | C9: =0 -> 0 | D9: =(1-Assumptions!$D$38)*Assumptions!$D$39/Assumptions!$D$8*'Cohort engine'!$D$32 -> 209.5958 | E9: =Assumptions!$D$42*'Cohort engine'!$D$32 -> 419.1916 | F9: B: eligible not on higher plan x upgrade rate x months retained at control churn. C: exposed x take rate x months retained. Both assumed fully incremental (favours B and C)
A10: Direct revenue from the paid feature | B10: INR | C10: =0 -> 0 | D10: =D9*Assumptions!$D$40 -> 209595.8 | E10: =E9*Assumptions!$D$41 -> 209176.61 | F10: billed account-months x uplift or add-on price
A11: Total attributable revenue | B11: INR | C11: =C8+C10 -> 234498.42 | D11: =D8+D10 -> 256495.48 | E11: =E8+E10 -> 302975.97 | F11: retention + direct
A12: Variable: payment/billing fees | B12: INR | C12: =C10*Assumptions!$D$44 -> 0 | D12: =D10*Assumptions!$D$44 -> 4191.916 | E12: =E10*Assumptions!$D$44 -> 4183.5322 | F12: direct revenue x fee
A13: Variable: serving cost of revenue | B13: INR | C13: =C11*(1-Assumptions!$D$23) -> 35174.762 | D13: =D11*(1-Assumptions!$D$23) -> 38474.322 | E13: =E11*(1-Assumptions!$D$23) -> 45446.396 | F13: revenue x (1 - gross margin)
A14: Variable: AI token cost | B14: INR | C14: ='Cohort engine'!$D$31*Assumptions!$D$10*Assumptions!$D$31*Assumptions!$D$30*'Cost model'!$D$11 -> 0 | D14: ='Cohort engine'!$D$31*Assumptions!$D$10*Assumptions!$D$31*Assumptions!$D$30*'Cost model'!$D$11 -> 0 | E14: ='Cohort engine'!$D$31*Assumptions!$D$10*Assumptions!$D$31*Assumptions!$D$30*'Cost model'!$D$11 -> 0 | F14: same for all options; 0 while AI is off
A15: Gross profit | B15: INR | C15: =C11-C12-C13-C14 -> 199323.65 | D15: =D11-D12-D13-D14 -> 213829.24 | E15: =E11-E12-E13-E14 -> 253346.05 | F15: revenue - variable costs
A16: Gross margin | B16: % of revenue | C16: =IF(C11=0,0,C15/C11) -> 0.85 | D16: =IF(D11=0,0,D15/D11) -> 0.83365696 | E16: =IF(E11=0,0,E15/E11) -> 0.83619187 | F16: gross profit / revenue
A17: Fixed programme cost over horizon | B17: INR | C17: ='Cost model'!$D$9*Assumptions!$D$20 -> 444000 | D17: ='Cost model'!$D$9*Assumptions!$D$20 -> 444000 | E17: ='Cost model'!$D$9*Assumptions!$D$20 -> 444000 | F17: identical for all options (same cost basis)
A18: One-time billing/entitlement build cost | B18: INR | C18: =0 -> 0 | D18: =Assumptions!$D$46 -> 0 | E18: =Assumptions!$D$46 -> 0 | F18: 0 by default; raise on Assumptions to test
A19: Operating contribution over horizon | B19: INR | C19: =C15-C17-C18 -> -244676.35 | D19: =D15-D17-D18 -> -230170.76 | E19: =E15-E17-E18 -> -190653.95 | F19: gross profit - fixed - build (kept separate from gross margin)
A20: ROI on total programme cost | B20: % | C20: =IF(C17+C18+C14=0,0,C19/(C17+C18+C14)) -> -0.55107285 | D20: =IF(D17+D18+D14=0,0,D19/(D17+D18+D14)) -> -0.5184026 | E20: =IF(E17+E18+E14=0,0,E19/(E17+E18+E14)) -> -0.4294008 | F20: contribution / (fixed + build + AI)
A21: Highest modelled operating contribution | C21: =INDEX(C5:E5,MATCH(MAX(C19:E19),C19:E19,0)) -> C: Paid add-on
A22: Best option minus Option A (INR over horizon) | C22: =MAX(C19:E19)-C19 -> 54022.393
A23: Check: add-on buyers as a share of all activations under Option C (must be <= 100%) | E23: =IF('Adoption funnel'!$D$10*E6=0,0,Assumptions!$D$42/('Adoption funnel'!$D$10*E6)) -> 0.58356676
A24: Add-on take rate at which Option C equals Option A (given the friction assumption) | E24: =IF(E10=0,0,Assumptions!$D$42*((C8*Assumptions!$D$23*(1-E6)+E18)/(Assumptions!$D$23-Assumptions!$D$44))/E10) -> 0.020665225
A26: Scenario 2 (recurring monthly rollout), Base inputs
A27: Item | B27: Unit | C27: A: Free for all eligible | D27: B: Higher plan only | E27: C: Paid add-on | F27: Logic
A28: Adoption factor vs free version | B28: x | C28: =1 -> 1 | D28: =Assumptions!$D$38 -> 0.2 | E28: =Assumptions!$D$43 -> 0.4 | F28: A: 100%. B: only accounts already on the higher plan see it. C: guessed share surviving a paywall
A29: Incremental retained account-months from discovery | B29: account-months | C29: ='Revenue and business case'!$D$35*C28 -> 110.94643 | D29: ='Revenue and business case'!$D$35*D28 -> 22.189286 | E29: ='Revenue and business case'!$D$35*E28 -> 44.378572 | F29: scenario account-months x factor
A30: Plan revenue from the retention effect | B30: INR | C30: =C29*Assumptions!$D$22 -> 277366.08 | D30: =D29*Assumptions!$D$22 -> 55473.215 | E30: =E29*Assumptions!$D$22 -> 110946.43 | F30: account-months x price
A31: Billed account-months of the paid feature | B31: account-months | C31: =0 -> 0 | D31: =(1-Assumptions!$D$38)*Assumptions!$D$39/Assumptions!$D$8*'Cohort engine'!$D$35 -> 273.6 | E31: =Assumptions!$D$42*'Cohort engine'!$D$35 -> 547.2 | F31: B: eligible not on higher plan x upgrade rate x months retained at control churn. C: exposed x take rate x months retained. Both assumed fully incremental (favours B and C)
A32: Direct revenue from the paid feature | B32: INR | C32: =0 -> 0 | D32: =D31*Assumptions!$D$40 -> 273600 | E32: =E31*Assumptions!$D$41 -> 273052.8 | F32: billed account-months x uplift or add-on price
A33: Total attributable revenue | B33: INR | C33: =C30+C32 -> 277366.08 | D33: =D30+D32 -> 329073.22 | E33: =E30+E32 -> 383999.23 | F33: retention + direct
A34: Variable: payment/billing fees | B34: INR | C34: =C32*Assumptions!$D$44 -> 0 | D34: =D32*Assumptions!$D$44 -> 5472 | E34: =E32*Assumptions!$D$44 -> 5461.056 | F34: direct revenue x fee
A35: Variable: serving cost of revenue | B35: INR | C35: =C33*(1-Assumptions!$D$23) -> 41604.911 | D35: =D33*(1-Assumptions!$D$23) -> 49360.982 | E35: =E33*(1-Assumptions!$D$23) -> 57599.885 | F35: revenue x (1 - gross margin)
A36: Variable: AI token cost | B36: INR | C36: ='Cohort engine'!$D$34*Assumptions!$D$10*Assumptions!$D$31*Assumptions!$D$30*'Cost model'!$D$11 -> 0 | D36: ='Cohort engine'!$D$34*Assumptions!$D$10*Assumptions!$D$31*Assumptions!$D$30*'Cost model'!$D$11 -> 0 | E36: ='Cohort engine'!$D$34*Assumptions!$D$10*Assumptions!$D$31*Assumptions!$D$30*'Cost model'!$D$11 -> 0 | F36: same for all options; 0 while AI is off
A37: Gross profit | B37: INR | C37: =C33-C34-C35-C36 -> 235761.16 | D37: =D33-D34-D35-D36 -> 274240.23 | E37: =E33-E34-E35-E36 -> 320938.29 | F37: revenue - variable costs
